Workbook

Sheet SEGMENTO-01
A1: RESUMO DA TERRAPLENAGEM POR EIXO DE PROJETO
A2: Projeto:1095 km 701+000 ao km714+000 | B2: BR-163/MT | R2: ATUALIZAÇÃO : | S2: 46235
A3: Localização | B3: Estaca | H3: Extensão (m) | I3: Volumes | N3: Volumes | R3: agosto
I4: Escavação | K4: PRIMITIVO | N4: Escavação | O4: EXECUTADO | P4: Saldo Total Aterro (m³) | R4: EXECUTADO | S4: Saldo Total Aterro (m³)
B5: Início | E5: Final | I5: Corte 1ª (m³) | J5: Rebaixo do Subleito (m³) | K5: Aterro (Corpo) (m³) | L5: Aterro (Rebaixo do Subleito) (m³) | M5: Total Aterro (m³) | N5: Corte 1ª (m³) | O5: Aterro (Corpo) (m³) | Q5: % | R5: Aterro (Corpo) (m³)
A6: RODOVIA
A7: BR-163-MT-Pista Sul - Duplicação | B7: 701 | C7: + | D7: 0 | E7: 702 | F7: + | G7: 0 | H7: =(E7*1000+G7)-(B7*1000+D7) -> 1000 | K7: 4881.4 | L7: 8197.33 | M7: 13078.73 | O7: =M7-P7 -> 0 | P7: 13078.73 | Q7: =(R7/M7)*1 -> 0 | S7: 10775.1
A8: GALERIA.3000X3000 | B8: 701 | C8: + | D8: 867 | E8: 702 | F8: + | G8: 0 | H8: =(E8*1000+G8)-(B8*1000+D8) -> 133 | K8: 1492.4 | N8: =N9-L8 -> 0
A9: BR-163-MT-Pista Sul - Duplicação | B9: 702 | C9: + | D9: 0 | E9: 703 | F9: + | G9: 0 | H9: =(E9*1000+G9)-(B9*1000+D9) -> 1000 | K9: 7646.288 | L9: 7651.8416 | M9: 15298.13 | O9: =M9-P9 -> 0 | P9: 15298.13 | Q9: =(O9/M9)*1 -> 0 | S9: 11528.4
A10: GALERIA.3000X3000 | B10: 702 | C10: + | D10: 0 | E10: 702 | F10: + | G10: 267 | H10: =(E10*1000+G10)-(B10*1000+D10) -> 267 | K10: 5452.1 | N10: =N11-L10 -> 0
A11: BR-163-MT-Pista Sul - Duplicação | B11: 703 | C11: + | D11: 0 | E11: 704 | F11: + | G11: 0 | H11: =(E11*1000+G11)-(B11*1000+D11) -> 1000 | K11: 4235.192 | L11: 6996.5688 | M11: 11231.761 | O11: =M11-P11 -> 0 | P11: 11231.761 | Q11: =(R11/M11)*1 -> 0 | S11: 0
A12: BR-163-MT-Pista Sul - Duplicação | B12: 704 | C12: + | D12: 0 | E12: 705 | F12: + | G12: 0 | H12: =(E12*1000+G12)-(B12*1000+D12) -> 1000 | K12: 12299.976 | L12: 4674.7069 | M12: 16974.683 | O12: =M12-P12 -> 0 | P12: 16974.683 | Q12: =(R12/M12)*1 -> 0 | S12: 8671.5
A13: GALERIA.3500X3500 | B13: 704 | C13: + | D13: 435 | E13: 704 | F13: + | G13: 835 | H13: =(E13*1000+G13)-(B13*1000+D13) -> 400 | K13: 9180.4
A14: BR-163-MT-Pista Sul - Duplicação | B14: 705 | C14: + | D14: 0 | E14: 706 | F14: + | G14: 0 | H14: =(E14*1000+G14)-(B14*1000+D14) -> 1000 | K14: 4061.1 | L14: 6384 | M14: 10445.1 | O14: =M14-P14 -> 0 | P14: 10445.1 | Q14: =(O14/M14)*1 -> 0 | R14: =P14-S14 -> 10445.1 | S14: 0
A15: BR-163-MT-Pista Sul - Duplicação | B15: 706 | C15: + | D15: 0 | E15: 707 | F15: + | G15: 0 | H15: =(E15*1000+G15)-(B15*1000+D15) -> 1000 | K15: 9060.7 | L15: 4674.7069 | M15: 13735.407 | O15: =M15-P15 -> 0 | P15: 13735.407 | Q15: =(O15/M15)*1 -> 0 | S15: 0
A16: RETORNO | B16: 706 | C16: + | D16: 400 | E16: 707 | F16: + | G16: 0 | H16: =(E16*1000+G16)-(B16*1000+D16) -> 600 | K16: 5804.3
A17: BR-163-MT-Pista Sul - Duplicação | B17: 707 | C17: + | D17: 0 | E17: 708 | F17: + | G17: 0 | H17: =(E17*1000+G17)-(B17*1000+D17) -> 1000 | K17: 9622.3 | L17: 0 | M17: 483.6 | O17: =(M17-P17)+R17 -> 0 | P17: 483.6 | Q17: =(O17/M17)*1 -> 0 | S17: 0
A18: BR-163-MT-Pista Sul - Duplicação | B18: 708 | C18: + | D18: 0 | E18: 709 | F18: + | G18: 0 | H18: =(E18*1000+G18)-(B18*1000+D18) -> 1000 | K18: 13702.4 | L18: 0 | M18: 3182.4 | O18: =M18-P18 -> 0 | P18: 3182.4 | Q18: =(O18/M18)*1 -> 0 | S18: 0
A19: BR-163-MT-Pista Sul - Duplicação | B19: 709 | C19: + | D19: 0 | E19: 710 | F19: + | G19: 0 | H19: =(E19*1000+G19)-(B19*1000+D19) -> 1000 | K19: 14950.3 | L19: 0 | M19: 7668.8 | O19: =M19-P19 -> 0 | P19: 7668.8 | Q19: =(O19/M19)*1 -> 0 | R19: =P19-S19 -> 7668.8 | S19: 0
A20: BR-163-MT-Pista Sul - Duplicação | B20: 710 | C20: + | D20: 0 | E20: 711 | F20: + | G20: 0 | H20: =(E20*1000+G20)-(B20*1000+D20) -> 1000 | K20: 14767.3 | L20: 1623.6 | M20: 8254.7 | O20: =M20-P20 -> 0 | P20: 8254.7 | Q20: =(O20/M20)*1 -> 0 | S20: 0
A21: RETORNO | B21: 710 | C21: + | D21: 600 | E21: 711 | F21: + | G21: 0 | H21: =(E21*1000+G21)-(B21*1000+D21) -> 400 | K21: 3739
A22: BR-163-MT-Pista Sul - Duplicação | B22: 711 | C22: + | D22: 0 | E22: 712 | F22: + | G22: 0 | H22: =(E22*1000+G22)-(B22*1000+D22) -> 1000 | K22: 2757.6 | L22: 5903.9 | M22: 2867.8 | O22: =(M22-P22)+R22 -> 0 | P22: 2867.8 | Q22: =(O22/M22)*1 -> 0 | S22: 0
A23: RETORNO | B23: 711 | D23: 0 | E23: 711 | F23: + | G23: 540 | H23: =(E23*1000+G23)-(B23*1000+D23) -> 540 | K23: 1785.4
A24: BR-163-MT-Pista Sul - Duplicação | B24: 712 | C24: + | D24: 0 | E24: 713 | F24: + | G24: 0 | H24: =(E24*1000+G24)-(B24*1000+D24) -> 1000 | K24: 373.1 | L24: 7380 | M24: 2058.9 | O24: =M24-P24 -> 0 | P24: 2058.9 | Q24: =(O24/M24)*1 -> 0 | R24: =P24-S24 -> 2058.9 | S24: 0
A25: BR-163-MT-Pista Sul - Duplicação | B25: 713 | C25: + | D25: 0 | E25: 714 | F25: + | G25: 0 | H25: =(E25*1000+G25)-(B25*1000+D25) -> 1000 | K25: 6579.9 | L25: 7156.8 | M25: 8854.8 | O25: =(M25-P25)+R25 -> 8854.8 | P25: 8854.8 | Q25: =(O25/M25)*1 -> 1 | R25: 8854.8 | S25: 0
A26: BR-163-MT-Pista Sul - Duplicação | B26: 714 | C26: + | D26: 0 | E26: 715 | F26: + | G26: 0 | H26: =(E26*1000+G26)-(B26*1000+D26) -> 1000 | K26: 3271.5 | L26: 6384.4 | M26: 2573.2 | O26: =(M26-P26)+R26 -> 2573.2 | P26: 2573.2 | Q26: =(O26/M26)*1 -> 1 | R26: =P26 -> 2573.2 | S26: 0
A27: BR-163-MT-Pista Sul - Duplicação | B27: 715 | C27: + | D27: 0 | E27: 716 | F27: + | G27: 0 | H27: =(E27*1000+G27)-(B27*1000+D27) -> 1000 | K27: 19504.2 | L27: 0 | M27: 2340.7 | O27: =(M27-P27)+R27 -> 2340.7 | P27: 2340.7 | Q27: =(O27/M27)*1 -> 1 | R27: =P27 -> 2340.7 | S27: 0
A28: BR-163-MT-Pista Sul - Duplicação | B28: 716 | C28: + | D28: 0 | E28: 717 | F28: + | G28: 0 | H28: =(E28*1000+G28)-(B28*1000+D28) -> 1000 | K28: 22751.3 | L28: 0 | M28: 1523 | O28: =(M28-P28)+R28 -> 1523 | P28: 1523 | Q28: =(O28/M28)*1 -> 1 | R28: =P28 -> 1523 | S28: 0
A29: ="TOTAL - "&A6 -> TOTAL - RODOVIA | I29: =SUM(I7:I25) -> 0 | J29: =SUM(J7:J25) -> 0 | K29: =SUM(K7:K25) -> 132391.16 | L29: =SUM(L7:L25) -> 60643.454 | M29: =SUM(M7:M25) -> 114134.81 | O29: =SUM(O7:O25) -> 8854.8 | P29: =SUM(P7:P25) -> 114134.81 | S29: =SUM(S7:S28) -> 30975

Sheet SEGMENTO-02
A1: RESUMO DA TERRAPLENAGEM POR EIXO DE PROJETO
A2: Projeto:1095 km 701+000 ao km713+500 | B2: BR-163/MT | R2: ATUALIZAÇÃO : | S2: ='SEGMENTO-01'!S2 -> 46235
A3: Localização | B3: Estaca | H3: Extensão (m) | I3: Volumes | N3: Volumes | R3: agosto
I4: Escavação | K4: PRIMITIVO | N4: Escavação | O4: EXECUTADO | R4: EXECUTADO
B5: Início | E5: Final | I5: Corte 1ª (m³) | J5: Rebaixo do Subleito (m³) | K5: Aterro (Corpo) (m³) | L5: Aterro (Rebaixo do Subleito) (m³) | M5: Total Aterro (m³) | N5: Corte 1ª (m³) | O5: Aterro (Corpo) (m³) | P5: Saldo Total Aterro (m³) | Q5: % | R5: Aterro (Corpo) (m³) | S5: Saldo Total Aterro (m³) | U5: vol. seg-03 732+00_736+380 sul
A6: RODOVIA
A7: BR-163-MT-Pista Sul - Duplicação | B7: 732 | C7: + | D7: 0 | E7: 733 | F7: + | G7: 0 | H7: =(E7*1000+G7)-(B7*1000+D7) -> 1000 | K7: 3681.8 | L7: 0 | M7: =(K7+L7) -> 3681.8 | O7: 0 | P7: =K7 -> 3681.8 | Q7: =(O7/M7)*1 -> 0 | S7: 759.7 | U7: 732 | V7: + | W7: 0 | X7: 733 | Y7: + | Z7: 0 | AA7: =S7 -> 759.7
A8: BR-163-MT-Pista Sul - Duplicação | B8: 733 | C8: + | D8: 0 | E8: 734 | F8: + | G8: 0 | H8: =(E8*1000+G8)-(B8*1000+D8) -> 1000 | K8: 1041.5 | L8: 0 | M8: 3041.5 | O8: 0 | P8: =K8 -> 1041.5 | Q8: =(O8/M8)*1 -> 0 | S8: 569.6 | U8: 733 | V8: + | W8: 0 | X8: 734 | Y8: + | Z8: 0 | AA8: =S8 -> 569.6
A9: BR-163-MT-Pista Sul - Duplicação | B9: 734 | C9: + | D9: 0 | E9: 735 | F9: + | G9: 0 | H9: =(E9*1000+G9)-(B9*1000+D9) -> 1000 | K9: 10181.8 | L9: 0 | M9: =(K9+L9) -> 10181.8 | O9: 0 | P9: =K9 -> 10181.8 | Q9: =(O9/M9)*1 -> 0 | S9: 1311.5 | U9: 734 | V9: + | W9: 0 | X9: 735 | Y9: + | Z9: 0 | AA9: =S9 -> 1311.5
A10: BR-163-MT-Pista Sul - Duplicação | B10: 735 | C10: + | D10: 0 | E10: 736 | F10: + | G10: 0 | H10: =(E10*1000+G10)-(B10*1000+D10) -> 1000 | K10: 4226.6 | L10: 0 | M10: =(K10+L10) -> 4226.6 | O10: 0 | P10: =K10 -> 4226.6 | Q10: =(O10/M10)*1 -> 0 | S10: 297.2 | U10: 735 | V10: + | W10: 0 | X10: 736 | Y10: + | Z10: 0 | AA10: =S10 -> 297.2
A11: BR-163-MT-Pista Sul - Duplicação | B11: 736 | C11: + | D11: 0 | E11: 736 | F11: + | G11: 380 | H11: =(E11*1000+G11)-(B11*1000+D11) -> 380 | L11: 0 | M11: 8396.8 | O11: 0 | P11: 8396.8 | S11: 8396.8 | U11: 736 | V11: + | W11: 0 | X11: 736 | Y11: + | Z11: 380 | AA11: 8396.8
A12: BR-163-MT-Pista norte Restauração | B12: 732 | C12: + | D12: 0 | E12: 733 | F12: + | G12: 0 | H12: =(E12*1000+G12)-(B12*1000+D12) -> 1000 | K12: 11152.5 | L12: 0 | M12: =(K12+L12) -> 11152.5 | O12: 0 | P12: =K12 -> 11152.5 | Q12: =(O12/M12)*1 -> 0 | S12: 11029.7 | AA12: =SUM(AA7:AA11) -> 11334.8
A13: BR-163-MT-Pista norte Restauração | B13: 733 | C13: + | D13: 0 | E13: 734 | F13: + | G13: 0 | H13: =(E13*1000+G13)-(B13*1000+D13) -> 1000 | K13: 11949.9 | L13: 0 | M13: 11949.9 | O13: 0 | P13: 11949.9 | Q13: =(O13/M13)*1 -> 0 | S13: 10292
A14: BR-163-MT-Pista norte Restauração | B14: 734 | C14: + | D14: 0 | E14: 734 | F14: + | G14: 220 | H14: =(E14*1000+G14)-(B14*1000+D14) -> 220 | K14: 3186.1 | L14: 0 | M14: =(K14+L14) -> 3186.1 | O14: 0 | P14: =K14 -> 3186.1 | Q14: =(O14/M14)*1 -> 0 | S14: 3186.1 | U14: vol. seg-03 732+000 ao 734+220 norte
A15: ="TOTAL - "&A6 -> TOTAL - RODOVIA | I15: =SUM(I7:I14) -> 0 | J15: =SUM(J7:J14) -> 0 | K15: =SUM(K7:K14) -> 45420.2 | L15: =SUM(L7:L14) -> 0 | M15: =SUM(M7:M14) -> 55817 | O15: =SUM(O7:O14) -> 0 | P15: =SUM(P7:P14) -> 53817 | S15: =SUM(S7:S14) -> 35842.6
U16: 732 | V16: + | W16: 0 | X16: 733 | Y16: + | Z16: 0 | AA16: =S12 -> 11029.7
U17: 733 | V17: + | W17: 0 | X17: 734 | Y17: + | Z17: 0 | AA17: =S13 -> 10292
U18: 734 | V18: + | W18: 0 | X18: 734 | Y18: + | Z18: 220 | AA18: =S14 -> 3186.1
AA19: =SUM(AA16:AA18) -> 24507.8

Sheet nv. greide SEGMENTO-03
A1: RESUMO DA TERRAPLENAGEM POR EIXO DE PROJETO
A2: Projeto:1097 km 736+640 ao km 745+500 | B2: BR-163/MT | N2: ATUALIZAÇÃO : | O2: ='SEGMENTO-01'!S2 -> 46235
A3: Localização | B3: Estaca | H3: Extensão (m) | N3: agosto
J4: Compactação | N4: EXECUTADO
B5: Início | E5: Final | I5: Rebaixo do Subleito (m³) | J5: Aterro (Corpo) (m³) | K5: Aterro (Acabamento) (m³) | L5: Aterro (Rebaixo do Subleito) (m³) | M5: Total Aterro (m³) | N5: Aterro (Corpo) (m³) | O5: Saldo Total Aterro (m³) | Q5: vol. seg-03 736+640_745+515
A6: RODOVIA
A7: BR-163-MT-Pista Sul - Duplicação | B7: 736 | C7: + | D7: 0 | E7: 736 | F7: + | G7: 380 | H7: =(E7*1000+G7)-(B7*1000+D7) -> 380 | J7: 32188.2 | K7: 0 | L7: 442.8 | M7: =J7+K7+L7 -> 32631 | O7: =27292.1-O8 -> 8396.8 | Q7: 736 | R7: + | S7: 0 | T7: 736 | U7: + | V7: 380
A8: BR-163-MT-Pista Sul - Duplicação | B8: 736 | C8: + | D8: 640 | E8: 737 | F8: + | G8: 0 | H8: =(E8*1000+G8)-(B8*1000+D8) -> 360 | J8: 32188.2 | K8: 0 | L8: 442.8 | M8: =J8+K8+L8-8396.8 -> 24234.2 | N8: =M8-O8 -> 5338.9 | O8: 18895.3 | Q8: 736 | R8: + | S8: 640 | T8: 737 | U8: + | V8: 0 | W8: 18895.3
A9: BR-163-MT-Pista Sul - Duplicação | B9: 737 | C9: + | D9: 0 | E9: 738 | F9: + | G9: 0 | H9: =(E9*1000+G9)-(B9*1000+D9) -> 1000 | J9: 3103.1 | K9: 0 | L9: 5977.7 | M9: =J9+K9+L9 -> 9080.8 | N9: =M9 -> 9080.8 | O9: 0 | Q9: 737 | R9: + | S9: 0 | T9: 738 | U9: + | V9: 0 | W9: =O9 -> 0
A10: BR-163-MT-Pista Sul - Duplicação | B10: 738 | C10: + | D10: 0 | E10: 739 | F10: + | G10: 0 | H10: =(E10*1000+G10)-(B10*1000+D10) -> 1000 | J10: 16351.8 | K10: 0 | L10: 3653.4 | M10: =J10+K10+L10 -> 20005.2 | N10: =M10-O10 -> 19699 | O10: 306.2 | Q10: 738 | R10: + | S10: 0 | T10: 739 | U10: + | V10: 0 | W10: =O10 -> 306.2
A11: BR-163-MT-Pista Sul - Duplicação | B11: 739 | C11: + | D11: 0 | E11: 740 | F11: + | G11: 0 | H11: =(E11*1000+G11)-(B11*1000+D11) -> 1000 | J11: 13604.5 | K11: 0 | L11: 3822.8 | M11: =J11+K11+L11 -> 17427.3 | N11: =M11-O11 -> 17136.5 | O11: 290.8 | Q11: 739 | R11: + | S11: 0 | T11: 740 | U11: + | V11: 0 | W11: =O11 -> 290.8
A12: BR-163-MT-Pista Sul - Duplicação | B12: 740 | C12: + | D12: 0 | E12: 741 | F12: + | G12: 0 | H12: =(E12*1000+G12)-(B12*1000+D12) -> 1000 | J12: 4863.4 | K12: 0 | L12: 4904 | M12: =J12+K12+L12 -> 9767.4 | N12: =M12-O12 -> 8356.2 | O12: 1411.2 | Q12: 740 | R12: + | S12: 0 | T12: 741 | U12: + | V12: 0 | W12: =O12 -> 1411.2
A13: BR-163-MT-Pista Sul - Duplicação | B13: 741 | C13: + | D13: 0 | E13: 742 | F13: + | G13: 0 | H13: =(E13*1000+G13)-(B13*1000+D13) -> 1000 | J13: 3883.7 | K13: 0 | L13: 4804 | M13: =J13+K13+L13 -> 8687.7 | N13: =M13-O13 -> 3100.4 | O13: 5587.3 | Q13: 741 | R13: + | S13: 0 | T13: 742 | U13: + | V13: 0 | W13: =O13 -> 5587.3
A14: BR-163-MT-Pista Sul - Duplicação | B14: 742 | C14: + | D14: 0 | E14: 743 | F14: + | G14: 0 | H14: =(E14*1000+G14)-(B14*1000+D14) -> 1000 | J14: 2483 | K14: 0 | L14: 6588.4 | M14: =J14+K14+L14 -> 9071.4 | N14: =M14-O14 -> 5746.64 | O14: 3324.76 | Q14: 742 | R14: + | S14: 0 | T14: 743 | U14: + | V14: 0 | W14: =O14 -> 3324.76
A15: BR-163-MT-Pista Sul - Duplicação | B15: 743 | C15: + | D15: 0 | E15: 744 | F15: + | G15: 0 | H15: =(E15*1000+G15)-(B15*1000+D15) -> 1000 | J15: 20284 | K15: 0 | L15: 304.3 | M15: =J15+K15+L15 -> 20588.3 | N15: =M15-O15 -> 6701.7 | O15: 13886.6 | Q15: 743 | R15: + | S15: 0 | T15: 744 | U15: + | V15: 0 | W15: =O15 -> 13886.6
A16: BR-163-MT-Pista Sul - Duplicação | B16: 744 | C16: + | D16: 0 | E16: 745 | F16: + | G16: 0 | H16: =(E16*1000+G16)-(B16*1000+D16) -> 1000 | J16: 4959.3 | K16: 0 | L16: 5272.3 | M16: =J16+K16+L16 -> 10231.6 | N16: =M16-O16 -> 0 | O16: 10231.6 | Q16: 744 | R16: + | S16: 0 | T16: 745 | U16: + | V16: 0 | W16: =O16 -> 10231.6
A17: BR-163-MT-Pista Sul - Duplicação | B17: 745 | C17: + | D17: 515 | E17: 746 | F17: + | G17: 0 | H17: =(E17*1000+G17)-(B17*1000+D17) -> 485 | J17: 7203.3 | K17: 0 | L17: 1133.9 | M17: =J17+K17+L17 -> 8337.2 | N17: =M17-O17 -> 0 | O17: 8337.2 | Q17: 745 | R17: + | S17: 515 | T17: 746 | U17: + | V17: 0 | W17: =O17 -> 8337.2
A18: ="TOTAL - "&A6 -> TOTAL - RODOVIA | I18: =SUM(I7:I17) -> 0 | J18: =SUM(J8:J17) -> 108924.3 | K18: =SUM(K8:K17) -> 0 | L18: =SUM(L8:L17) -> 36903.6 | M18: =SUM(M8:M17) -> 137431.1 | O18: =SUM(O8:O17) -> 62270.96 | W18: =SUM(W8:W17) -> 62270.96
A19: ACESSOS
A20: Acesso km 742+440 - RA | B20: 0 | C20: + | D20: 0 | E20: 0 | F20: + | G20: 41.869 | H20: 41.869 | J20: 0 | L20: 185.63511 | M20: =(J20+K20+L20) -> 185.63511
A21: Acesso km 742+440 - RB | B21: 0 | C21: + | D21: 0 | E21: 0 | F21: + | G21: 42.958 | H21: 42.958 | J21: 17.04443 | L21: 191.43624 | M21: =(J21+K21+L21) -> 208.48067
A22: Acesso km 743+830 - RA | B22: 0 | C22: + | D22: 0 | E22: 0 | F22: + | G22: 50.409 | H22: 50.409 | J22: 366.92171 | L22: 51.527 | M22: =(J22+K22+L22) -> 418.44871
A23: Acesso km 743+830 - RB | B23: 0 | C23: + | D23: 0 | E23: 0 | F23: + | G23: 49.919 | H23: 49.919 | J23: 466.38242 | L23: 51.05 | M23: =(J23+K23+L23) -> 517.43242
A24: ="TOTAL- ACESSOS" -> TOTAL- ACESSOS | I24: =SUM(I20:I23) -> 0 | J24: =SUM(J20:J23) -> 850.34856 | K24: =SUM(K20:K23) -> 0 | L24: =SUM(L20:L23) -> 479.64834 | M24: =SUM(M20:M23) -> 1329.9969 | O24: =M24 -> 1329.9969
A25: TOTAL GERAL | I25: =I18+I24 -> 0 | J25: =J18+J24 -> 109774.65 | K25: =K18+K24 -> 0 | L25: =L18+L24 -> 37383.248 | M25: =M18+M24 -> 138761.1 | O25: =O18+O24 -> 63600.957
I43: 7598.6
I44: 24589.6
I45: =I44+I43 -> 32188.2

Sheet INTERSEÇÃO - km 713+700
A1: RESUMO DA TERRAPLENAGEM POR EIXO DE PROJETO
A2: Projeto: | B2: BR-163/MT | O2: ATUALIZAÇÃO : | P2: ='SEGMENTO-01'!S2 -> 46235
A3: Localização | B3: Estaca | H3: Extensão (m) | I3: Volumes | O3: agosto
I4: Escavação | K4: Compactação | O4: EXECUTADO
B5: Início | E5: Final | I5: Corte 1ª (m³) | J5: Rebaixo do Subleito (m³) | K5: Aterro (Corpo) (m³) | L5: Aterro (Acabamento) (m³) | M5: Aterro (Rebaixo do Subleito) (m³) | N5: Total Aterro (m³) | O5: Aterro (Corpo) (m³) | P5: Saldo Total Aterro (m³)
A6: INTERSEÇÃO - km 713+700
A7: Ramo 100 | B7: 100 | C7: + | D7: 0 | E7: 100 | F7: + | G7: 365.897 | H7: =(E7*1000+G7)-(B7*1000+D7) -> 365.897 | I7: 0 | J7: 0 | K7: 38378.997 | L7: 2029.2253 | M7: 137.35 | N7: =(K7+L7+M7) -> 40545.572 | P7: 36236.4
A8: Ramo 200 | B8: 200 | C8: + | D8: 0 | E8: 200 | F8: + | G8: 234.645 | H8: =(E8*1000+G8)-(B8*1000+D8) -> 234.645 | I8: 0 | J8: 0 | K8: 1181.7283 | L8: 306.22654 | M8: 411.6367 | N8: =(K8+L8+M8) -> 1899.5916 | P8: 658.9
A9: Ramo 300 | B9: 300 | C9: + | D9: 0 | E9: 300 | F9: + | G9: 82.816 | H9: =(E9*1000+G9)-(B9*1000+D9) -> 82.816 | I9: 0 | J9: 0 | K9: 7.005445 | L9: 0 | M9: 321.47769 | N9: =(K9+L9+M9) -> 328.48314 | P9: 13.1
A10: RA | B10: 0 | C10: + | D10: 0 | E10: 0 | F10: + | G10: 44.966 | H10: =(E10*1000+G10)-(B10*1000+D10) -> 44.966 | I10: 0 | J10: 0 | K10: 407.42303 | L10: 154.72773 | M10: 0 | N10: =(K10+L10+M10) -> 562.15076 | P10: 221.6
A11: RB | B11: 0 | C11: + | D11: 0 | E11: 0 | F11: + | G11: 52.633 | H11: =(E11*1000+G11)-(B11*1000+D11) -> 52.633 | I11: 0 | J11: 0 | K11: 274.23911 | L11: 145.71521 | M11: 26.650055 | N11: =(K11+L11+M11) -> 446.60437 | P11: 196.6
A12: RC | B12: 0 | C12: + | D12: 0 | E12: 0 | F12: + | G12: 57.102 | H12: =(E12*1000+G12)-(B12*1000+D12) -> 57.102 | I12: 0 | J12: 0 | K12: 457.23714 | L12: 151.11228 | M12: 6.3 | N12: =(K12+L12+M12) -> 614.64941 | P12: 175.2
A13: RD | B13: 0 | C13: + | D13: 0 | E13: 0 | F13: + | G13: 37.15 | H13: =(E13*1000+G13)-(B13*1000+D13) -> 37.15 | I13: 0 | J13: 0 | K13: 17.79 | L13: 0 | M13: 154.48825 | N13: =(K13+L13+M13) -> 172.27825 | P13: 12.9
A14: RE | B14: 0 | C14: + | D14: 0 | E14: 0 | F14: + | G14: 28.673 | H14: =(E14*1000+G14)-(B14*1000+D14) -> 28.673 | I14: 0 | J14: 0 | K14: 3.002345 | L14: 0 | M14: 99.14918 | N14: =(K14+L14+M14) -> 102.15152 | P14: 49.1
A15: RF | B15: 0 | C15: + | D15: 0 | E15: 0 | F15: + | G15: 39.544 | H15: =(E15*1000+G15)-(B15*1000+D15) -> 39.544 | I15: 0 | J15: 0 | K15: 1.83152 | L15: 0 | M15: 231.17688 | N15: =(K15+L15+M15) -> 233.0084 | P15: 83.1
A16: Rotatória 01 | B16: 0 | C16: + | D16: 0 | E16: 0 | F16: + | G16: 94.248 | H16: =(E16*1000+G16)-(B16*1000+D16) -> 94.248 | I16: 0 | J16: 0 | K16: 1610.5877 | L16: 598.4066 | M16: 2.35 | N16: =(K16+L16+M16) -> 2211.3443 | P16: 868.2
A17: Rotatória 02 | B17: 0 | C17: + | D17: 0 | E17: 0 | F17: + | G17: 94.247 | H17: =(E17*1000+G17)-(B17*1000+D17) -> 94.247 | I17: 0 | J17: 0 | K17: 55.57597 | L17: 2.15 | M17: 588.432 | N17: =(K17+L17+M17) -> 646.15797 | P17: 117.9
A18: REBAIXOMENTO DO INT.km.713+700 R.100.ENCONTRO-0 | B18: 100 | C18: + | D18: 65 | E18: 100 | F18: + | G18: 115 | H18: =(E18*1000+G18)-(B18*1000+D18) -> 50 | K18: 1989 | N18: =(K18+L18+M18) -> 1989 | P18: 0
A19: REBAIXOMENTO DO INT.km.713+700 R.100.ENCONTRO-1 | B19: 100 | C19: + | D19: 115 | E19: 100 | F19: + | G19: 140 | H19: =(E19*1000+G19)-(B19*1000+D19) -> 25 | K19: 1719.75 | N19: =(K19+L19+M19) -> 1719.75 | P19: 219.75
A20: REBAIXOMENTO DO INT.km.713+700 R.100.ENCONTRO-1 | B20: 100 | C20: + | D20: 140 | E20: 100 | F20: + | G20: 155 | H20: =(E20*1000+G20)-(B20*1000+D20) -> 15 | K20: 1315.96 | N20: =(K20+L20+M20) -> 1315.96 | P20: 1015.96
A21: REBAIXOMENTO DO INT.km.713+700 R.100.ENCONTRO-2 | B21: 100 | C21: + | D21: 207 | E21: 100 | F21: + | G21: 275 | H21: =(E21*1000+G21)-(B21*1000+D21) -> 68 | K21: 8267 | N21: =(K21+L21+M21) -> 8267 | P21: 8267
A22: REBAIXOMENTO DO INT.km.713+700 R.100.ENCONTRO-2 | B22: 100 | C22: + | D22: 275 | E22: 100 | F22: + | G22: 290 | H22: =(E22*1000+G22)-(B22*1000+D22) -> 15 | K22: 1054.8 | N22: =(K22+L22+M22) -> 1054.8 | P22: 570
A23: REBAIXOMENTO DO INT.km.713+700 R.100.ENCONTRO-2 | B23: 100 | C23: + | D23: 29 | E23: 100 | F23: + | G23: 330 | H23: =(E23*1000+G23)-(B23*1000+D23) -> 301 | K23: 1466.6 | N23: =(K23+L23+M23) -> 1466.6 | P23: 763.49
A24: ="TOTAL - "&A6 -> TOTAL - INTERSEÇÃO - km 713+700 | I24: 0 | J24: =SUM(J7:J17) -> 0 | K24: =SUM(K7:K23) -> 58208.527 | L24: =SUM(L7:L17) -> 3387.5636 | M24: =SUM(M7:M17) -> 1979.0108 | N24: =SUM(N7:N23) -> 63575.102 | P24: =SUM(P7:P23) -> 49469.2 | Q24: =P24/N24 -> 0.77812223 | R24: =1-Q24 -> 0.22187777
A25: TRAVESSIA URBANA - PRIMAVERA
A26: Agulha Norte | B26: 714 | C26: + | D26: 107 | E26: 714 | F26: + | G26: 505.314 | H26: =(E26*1000+G26)-(B26*1000+D26) -> 398.314 | K26: 367.88185 | L26: 11.58665 | M26: 1068.4412 | N26: =(K26+L26+M26) -> 1447.9097 | P26: 1447.9097
A27: Marginal Norte | B27: 713 | C27: + | D27: 920 | E27: 715 | F27: + | G27: 413.267 | H27: =(E27*1000+G27)-(B27*1000+D27) -> 1493.267 | K27: 7637.6261 | L27: 1169.2128 | M27: 5354.1576 | N27: =(K27+L27+M27) -> 14160.997 | P27: 11669.5
A28: MN-Acesso km 713+940 - RA | B28: 0 | C28: + | D28: 0 | E28: 0 | F28: + | G28: 27.012 | H28: =(E28*1000+G28)-(B28*1000+D28) -> 27.012 | K28: 17.67994 | L28: 0.26398 | M28: 119.30892 | N28: =(K28+L28+M28) -> 137.25284 | P28: 137.25284
A29: MN-Acesso km 713+940 - RB | B29: 0 | C29: + | D29: 0 | E29: 0 | F29: + | G29: 27.012 | H29: =(E29*1000+G29)-(B29*1000+D29) -> 27.012 | K29: 6.538035 | L29: 0.1 | M29: 127.07259 | N29: =(K29+L29+M29) -> 133.71062 | P29: 133.71062
A30: MN-Acesso km 714+090 - RA | B30: 0 | C30: + | D30: 0 | E30: 0 | F30: + | G30: 27.013 | H30: =(E30*1000+G30)-(B30*1000+D30) -> 27.013 | K30: 14.59408 | L30: 0 | M30: 76.35121 | N30: =(K30+L30+M30) -> 90.94529 | P30: 90.94529
A31: MN-Acesso km 714+090 - RB | B31: 0 | C31: + | D31: 0 | E31: 0 | F31: + | G31: 27.011 | H31: =(E31*1000+G31)-(B31*1000+D31) -> 27.011 | K31: 14.87122 | L31: 0 | M31: 78.629475 | N31: =(K31+L31+M31) -> 93.500695 | P31: 93.500695
A32: MN-Acesso km 714+270 - RA | B32: 0 | C32: + | D32: 0 | E32: 0 | F32: + | G32: 27.01 | H32: =(E32*1000+G32)-(B32*1000+D32) -> 27.01 | K32: 31.46102 | L32: 0 | M32: 102.97062 | N32: =(K32+L32+M32) -> 134.43164 | P32: 134.43164
A33: MN-Acesso km 714+270 - RB | B33: 0 | C33: + | D33: 0 | E33: 0 | F33: + | G33: 27.014 | H33: =(E33*1000+G33)-(B33*1000+D33) -> 27.014 | K33: 44.83356 | L33: 0 | M33: 104.95433 | N33: =(K33+L33+M33) -> 149.78789 | P33: 149.78789
A34: Agulha Sul | B34: 714 | C34: + | D34: 110 | E34: 714 | F34: + | G34: 306.065 | H34: =(E34*1000+G34)-(B34*1000+D34) -> 196.065 | K34: 22.90904 | L34: 0 | M34: 529.49789 | N34: =(K34+L34+M34) -> 552.40693 | P34: 552.40693
A35: Marginal Sul | B35: 713 | C35: + | D35: 889 | E35: 715 | F35: + | G35: 405.44 | H35: =(E35*1000+G35)-(B35*1000+D35) -> 1516.44 | K35: 3341.9194 | L35: 852.66555 | M35: 2430.09 | N35: =(K35+L35+M35) -> 6624.6749 | P35: 6024.6749
A36: MS-Acesso km 713+990 - RA | B36: 0 | C36: + | D36: 0 | E36: 0 | F36: + | G36: 18.017 | H36: =(E36*1000+G36)-(B36*1000+D36) -> 18.017 | K36: 21.812565 | L36: 0 | M36: 45.189495 | N36: =(K36+L36+M36) -> 67.00206 | P36: 67.00206
A37: MS-Acesso km 713+990 - RB | B37: 0 | C37: + | D37: 0 | E37: 0 | F37: + | G37: 18.016 | H37: =(E37*1000+G37)-(B37*1000+D37) -> 18.016 | K37: 8.25248 | L37: 0 | M37: 37.14677 | N37: =(K37+L37+M37) -> 45.39925 | P37: 45.39925
... A40: MS-Acesso km 715+130 - RA | B40: 0 | C40: + | D40: 0 | E40: 0 | F40: + | G40: 9.488 | H40: =(E40*1000+G40)-(B40*1000+D40) -> 9.488 | K40: 0.24684 | L40: 0 | M40: 3.558 | N40: =(K40+L40+M40) -> 3.80484 | P40: 3.80484
A41: ="TOTAL - "&A25 -> TOTAL - TRAVESSIA URBANA - PRIMAVERA | I41: =SUM(I26:I40) -> 0 | J41: =SUM(J26:J40) -> 0 | K41: =SUM(K26:K40) -> 11547.726 | L41: =SUM(L26:L40) -> 2033.829 | M41: =SUM(M26:M40) -> 10202.664 | N41: =SUM(N26:N40) -> 23784.219 | O41: =SUM(O26:O40) -> 0 | P41: =SUM(P26:P40) -> 20692.723 | Q41: =P41/N41 -> 0.870019 | R41: =1-Q41 -> 0.129981
A42: TOTAL GERAL | I42: =I24+I41 -> 0 | J42: =J24+J41 -> 0 | K42: =K24+K41 -> 69756.253 | L42: =L24+L41 -> 5421.3926 | M42: =M24+M41 -> 12181.675 | N42: =N24+N41 -> 87359.321 | O42: =O24+O41 -> 0 | P42: =P24+P41 -> 70161.923

Sheet INTERSEÇÃO - km 746+320
A1: RESUMO DA TERRAPLENAGEM POR EIXO DE PROJETO
A2: Projeto: | B2: BR-163/MT
A3: Localização | B3: Estaca | H3: Extensão (m) | I3: Volume
I4: Escavação | K4: Compactação
B5: Início | E5: Final | I5: Corte 1ª (m³) | J5: Rebaixo do Subleito (m³) | K5: Aterro (Corpo) (m³) | L5: Aterro (Acabamento) (m³) | M5: Aterro (Rebaixo do Subleito) (m³) | N5: Total Aterro (m³)
A6: INTERSEÇÃO - km 746+320
A7: Rodovia BR-163/MT | B7: 746 | C7: + | D7: 20 | E7: 746 | F7: + | G7: 640 | H7: =(E7*1000+G7)-(B7*1000+D7) -> 620 | K7: 48169.55 | L7: 6561.6 | M7: 0 | N7: 50423.5
A8: Ramo 100 | B8: 100 | C8: + | D8: 0 | E8: 100 | F8: + | G8: 34.34 | H8: =(E8*1000+G8)-(B8*1000+D8) -> 34.34 | K8: 8.55 | L8: 0.55 | M8: 228.648 | N8: 232.4
A9: Ramo 200 | B9: 200 | C9: + | D9: 0 | E9: 200 | F9: + | G9: 602.761 | H9: =(E9*1000+G9)-(B9*1000+D9) -> 602.761 | K9: 2414.383 | L9: 484.41166 | M9: 1608.5802 | N9: 2649.1
A10: Acesso MT-560-RA | B10: 0 | C10: + | D10: 0 | E10: 0 | F10: + | G10: 112.831 | H10: =(E10*1000+G10)-(B10*1000+D10) -> 112.831 | K10: 73.76929 | L10: 0 | M10: 495.3497 | N10: 593.6
A11: Acesso MT-560-RB | B11: 0 | C11: + | D11: 0 | E11: 0 | F11: + | G11: 42.08 | H11: =(E11*1000+G11)-(B11*1000+D11) -> 42.08 | K11: 105.5164 | L11: 6.3948 | M11: 159.7832 | N11: 252.3
A12: RA | B12: 0 | C12: + | D12: 0 | E12: 0 | F12: + | G12: 72.731 | H12: =(E12*1000+G12)-(B12*1000+D12) -> 72.731 | K12: 85.938695 | L12: 2.015595 | M12: 197.98798 | N12: 232.8
A13: RB | B13: 0 | C13: + | D13: 0 | E13: 0 | F13: + | G13: 57.868 | H13: =(E13*1000+G13)-(B13*1000+D13) -> 57.868 | K13: 92.29768 | L13: 12.57037 | M13: 158.82104 | N13: 204.2
A14: RC | B14: 0 | C14: + | D14: 0 | E14: 0 | F14: + | G14: 79.886 | H14: =(E14*1000+G14)-(B14*1000+D14) -> 79.886 | K14: 74.48481 | L14: 20.90023 | M14: 202.64149 | N14: 262.3
A15: RD | B15: 0 | C15: + | D15: 0 | E15: 0 | F15: + | G15: 95.064 | H15: =(E15*1000+G15)-(B15*1000+D15) -> 95.064 | K15: 50.60776 | L15: 3.84494 | M15: 300.04487 | N15: 372.8
A16: RE | B16: 0 | C16: + | D16: 0 | E16: 0 | F16: + | G16: 39.27 | H16: =(E16*1000+G16)-(B16*1000+D16) -> 39.27 | K16: 125.89563 | L16: 61.48885 | M16: 78.7144 | N16: 173.1
A17: RF | B17: 0 | C17: + | D17: 0 | E17: 0 | F17: + | G17: 47.782 | H17: =(E17*1000+G17)-(B17*1000+D17) -> 47.782 | K17: 65.47474 | L17: 42.47189 | M17: 81.82452 | N17: 175.5
A18: Rotatória 01 | B18: 0 | C18: + | D18: 0 | E18: 0 | F18: + | G18: 125.664 | H18: =(E18*1000+G18)-(B18*1000+D18) -> 125.664 | K18: 166.85772 | L18: 10.61524 | M18: 698.15548 | N18: 936.1
A19: Rotatória 02 | B19: 0 | C19: + | D19: 0 | E19: 0 | F19: + | G19: 342.475 | H19: =(E19*1000+G19)-(B19*1000+D19) -> 342.475 | K19: 1263.0217 | L19: 361.95409 | M19: 1360.4014 | N19: 3294.2
A20: REBAIXOMENTO DOINTERSEÇÃO - km 746+320 | B20: 746 | C20: + | D20: 231 | E20: 746 | F20: + | G20: 289 | H20: =(E20*1000+G20)-(B20*1000+D20) -> 58 | K20: 4605 | N20: 8189.41
A21: REBAIXOMENTO DOINTERSEÇÃO - km 746+320 | B21: 746 | C21: + | D21: 289 | E21: 746 | F21: + | G21: 309 | H21: =(E21*1000+G21)-(B21*1000+D21) -> 20 | K21: 2635 | N21: 8454.86
A22: REBAIXOMENTO DOINTERSEÇÃO - km 746+320 | B22: 746 | C22: + | D22: 327 | E22: 746 | F22: + | G22: 347 | H22: =(E22*1000+G22)-(B22*1000+D22) -> 20 | K22: 2540 | N22: 0
A23: REBAIXOMENTO DOINTERSEÇÃO - km 746+320 | B23: 746 | C23: + | D23: 347 | E23: 746 | F23: + | G23: 421 | H23: =(E23*1000+G23)-(B23*1000+D23) -> 74 | K23: 9710 | N23: 0
A24: ="TOTAL - "&A6 -> TOTAL - INTERSEÇÃO - km 746+320 | I24: =SUM(I7:I19) -> 0 | J24: =SUM(J7:J19) -> 0 | K24: =SUM(K7:K23) -> 72186.347 | L24: =SUM(L7:L19) -> 7568.8177 | M24: =SUM(M7:M19) -> 5570.9523 | N24: =SUM(N7:N23) -> 76446.17
A25: TRAVESSIA URBANA - SORRISO
A26: Agulha Norte | B26: 746 | C26: + | D26: 635 | E26: 746 | F26: + | G26: 984.985 | H26: =(E26*1000+G26)-(B26*1000+D26) -> 349.985 | K26: 276.03921 | L26: 12.30027 | M26: 875.53875 | N26: 1212.1
A27: Marginal Norte - Segmento 01 | B27: 745 | C27: + | D27: 500 | E27: 746 | F27: + | G27: 234.913 | H27: =(E27*1000+G27)-(B27*1000+D27) -> 734.913 | K27: 1186.5333 | L27: 59.842385 | M27: 3199.1013 | N27: 3011.9
A28: Marginal Norte - Segmento 02 | B28: 746 | C28: + | D28: 390 | E28: 747 | F28: + | G28: 569.47 | H28: =(E28*1000+G28)-(B28*1000+D28) -> 1179.47 | K28: 1860.9288 | L28: 144.91239 | M28: 5128.2062 | N28: 6916.3
A29: MN-Acesso km 745+740 - RA | B29: 0 | C29: + | D29: 0 | E29: 0 | F29: + | G29: 21.09 | H29: =(E29*1000+G29)-(B29*1000+D29) -> 21.09 | K29: 9.4432 | L29: 0.03 | M29: 97.838125 | N29: 107.28133
A30: MN-Acesso km 745+740 - RB | B30: 0 | C30: + | D30: 0 | E30: 0 | F30: + | G30: 28.027 | H30: =(E30*1000+G30)-(B30*1000+D30) -> 28.027 | K30: 37.21026 | L30: 0.61937 | M30: 98.88047 | N30: 108
A31: MN-Acesso km 747+300 - RA | B31: 0 | C31: + | D31: 0 | E31: 0 | F31: + | G31: 30.799 | H31: =(E31*1000+G31)-(B31*1000+D31) -> 30.799 | K31: 5.05796 | L31: 84.69657 | M31: 215.24772 | N31: 164.8
A32: MN-Acesso km 747+300 - RB | B32: 0 | C32: + | D32: 0 | E32: 0 | F32: + | G32: 40.738 | H32: =(E32*1000+G32)-(B32*1000+D32) -> 40.738 | K32: 15.2911 | L32: 0.21196 | M32: 130.89334 | N32: 121.9
A33: MN-Acesso km 747+300 - RC | B33: 0 | C33: + | D33: 0 | E33: 0 | F33: + | G33: 29.472 | H33: =(E33*1000+G33)-(B33*1000+D33) -> 29.472 | K33: 0.5316 | L33: 0 | M33: 111.6834 | N33: 125
A34: Agulha Sul | B34: 746 | C34: + | D34: 610 | E34: 746 | F34: + | G34: 853.16 | H34: =(E34*1000+G34)-(B34*1000+D34) -> 243.16 | K34: 676.82934 | L34: 149.76863 | M34: 422.75738 | N34: 898.9
A35: Marginal Sul | B35: 746 | C35: + | D35: 520 | E35: 747 | F35: + | G35: 791.766 | H35: =(E35*1000+G35)-(B35*1000+D35) -> 1271.766 | K35: 2946.4489 | L35: 886.02851 | M35: 4933.5774 | N35: 7582.9
A36: MS-Acesso km 747+200 - RA | B36: 0 | C36: + | D36: 0 | E36: 0 | F36: + | G36: 40.015 | H36: =(E36*1000+G36)-(B36*1000+D36) -> 40.015 | K36: 27.05683 | L36: 0 | M36: 123.4923 | N36: 146.4
A37: MS-Acesso km 747+200 - RB | B37: 0 | C37: + | D37: 0 | E37: 0 | F37: + | G37: 40.609 | H37: =(E37*1000+G37)-(B37*1000+D37) -> 40.609 | K37: 18.577835 | L37: 4.595 | M37: 120.62302 | N37: 139.9
A38: ="TOTAL - "&A25 -> TOTAL - TRAVESSIA URBANA - SORRISO | I38: =SUM(I26:I37) -> 0 | J38: =SUM(J26:J37) -> 0 | K38: =SUM(K26:K37) -> 7059.9483 | L38: =SUM(L26:L37) -> 1343.0051 | M38: =SUM(M26:M37) -> 15457.839 | N38: =SUM(N26:N37) -> 20535.381
A39: ACESSOS
A40: Acesso km 755+250 | B40: 755 | C40: + | D40: 45.913 | E40: 755 | F40: + | G40: 585.555 | H40: =(E40*1000+G40)-(B40*1000+D40) -> 539.642 | L40: 167.50422 | N40: 167.50422
...

Sheet RESUMO DE VOLUMES
A1: Localização | B1: Estaca | H1: Extensão (m) | I1: JUNHO
B3: Início | E3: Final | I3: Saldo Total Aterro (m³) | L3: Saldo Terraplanagem | R3: Trecho | S3: Saldo Aterro (m³)
A4: RODOVIA | L4: Techos | M4: Previsto (m³) | N4: Executado (m³) | O4: Saldo m³ | R4: ="Seg-01: "&B5&"+"&TEXT(D5,"000")&" ao "&E5&"+"&TEXT(G5,"000") -> Seg-01: 701+000 ao 713+500 | S4: =I5 -> 30975
A5: BR-163-MT-Pista Sul - Duplicação | B5: 701 | C5: + | D5: 0 | E5: 713 | F5: + | G5: 500 | H5: =(E5*1000+G5)-(B5*1000+D5) -> 12500 | I5: ='SEGMENTO-01'!S29 -> 30975 | L5: Segmento 1 | M5: ='SEGMENTO-01'!M29 -> 114134.81 | N5: =M5-O5 -> 83159.81 | O5: ='SEGMENTO-01'!S29 -> 30975 | R5: ="Seg-02 Sul: "&'SEGMENTO-02'!U7&"+"&TEXT('SEGMENTO-02'!W7,"000")&" ao "&'SEGMENTO-02'!X11&"+"&TEXT('SEGMENTO-02'!Z11,"000") -> Seg-02 Sul: 732+000 ao 736+380 | S5: ='SEGMENTO-02'!AA12 -> 11334.8
A6: BR-163-MT-Pista Sul - Duplicação | B6: 732 | C6: + | D6: 0 | E6: 736 | F6: + | G6: 0 | H6: =(E6*1000+G6)-(B6*1000+D6) -> 4000 | I6: ='SEGMENTO-02'!S15 -> 35842.6 | L6: Segmento 2 | M6: ='SEGMENTO-02'!M15 -> 55817 | N6: =M6-O6 -> 19974.4 | O6: ='SEGMENTO-02'!S15 -> 35842.6 | R6: ="Seg-02 Norte: "&'SEGMENTO-02'!U16&"+"&TEXT('SEGMENTO-02'!W16,"000")&" ao "&'SEGMENTO-02'!X18&"+"&TEXT('SEGMENTO-02'!Z18,"000") -> Seg-02 Norte: 732+000 ao 734+220 | S6: ='SEGMENTO-02'!AA19 -> 24507.8
A7: BR-163-MT-Pista Sul - Duplicação | B7: 736 | C7: + | D7: 0 | E7: 745 | F7: + | G7: 500 | H7: =(E7*1000+G7)-(B7*1000+D7) -> 9500 | I7: ='nv. greide SEGMENTO-03'!O18 -> 62270.96 | L7: Segmento 3 | M7: ='nv. greide SEGMENTO-03'!M18 -> 137431.1 | N7: =M7-O7 -> 75160.14 | O7: ='nv. greide SEGMENTO-03'!O18 -> 62270.96 | R7: ="Seg-03: "&B7&"+"&TEXT(D7,"000")&" ao "&E7&"+"&TEXT(G7,"000") -> Seg-03: 736+000 ao 745+500 | S7: =I7 -> 62270.96
A8: INTERSEÇÃO - km 713+700 PRIMAVERA | I8: ='INTERSEÇÃO - km 713+700'!P42 -> 70161.923 | L8: Dispositivo Primavera | M8: ='INTERSEÇÃO - km 713+700'!N24 -> 63575.102 | N8: =M8-O8 -> 14105.902 | O8: ='INTERSEÇÃO - km 713+700'!P24 -> 49469.2 | R8: =A8 -> INTERSEÇÃO - km 713+700 PRIMAVERA | S8: =I8 -> 70161.923
A9: INTERSEÇÃO - km 746+320 SORRISO | I9: ='INTERSEÇÃO - km 746+320'!N47 -> 96981.551 | L9: Marginais Primavera | M9: ='INTERSEÇÃO - km 713+700'!N41 -> 23784.219 | N9: =M9-O9 -> 3091.4965 | O9: ='INTERSEÇÃO - km 713+700'!P41 -> 20692.723 | R9: =A9 -> INTERSEÇÃO - km 746+320 SORRISO | S9: =I9 -> 96981.551
L10: Dispositivo Sorriso | M10: ='INTERSEÇÃO - km 746+320'!N24 -> 76446.17 | N10: =M10-O10 -> 0 | O10: ='INTERSEÇÃO - km 746+320'!N24 -> 76446.17 | R10: TOTAL | S10: =SUM(S4:S9) -> 296232.03
H11: =SUM('[2]RESUMO DE VOLUMES'!$I$5:$I$7) -> 173978.1 | I11: =H11-H12 -> 23604.9 | L11: Marginais Sorriso | M11: ='INTERSEÇÃO - km 746+320'!N38 -> 20535.381 | N11: =M11-O11 -> 0 | O11: ='INTERSEÇÃO - km 746+320'!N38 -> 20535.381
H12: =SUM('[1]RESUMO DE VOLUMES'!$I$5:$I$7) -> 150373.2 | L12: Acesso Km 755 | M12: ='INTERSEÇÃO - km 746+320'!N46 -> 1344.4306 | N12: =M12-O12 -> 0 | O12: ='INTERSEÇÃO - km 746+320'!P46 -> 1344.4306
H13: =SUM(I5:I7) -> 129088.56 | L13: Acesso KMm 743-742 | M13: ='nv. greide SEGMENTO-03'!M24 -> 1329.9969 | N13: =M13-O13 -> 0 | O13: ='nv. greide SEGMENTO-03'!O24 -> 1329.9969
H14: =H12-H13 -> 21284.64
L15: Techos | M15: Previsto (m³) | N15: Executado (m³) | O15: Saldo m³
L16: Total dos Segmentos | M16: =SUM(M5:M7) -> 307382.91 | N16: =SUM(N5:N7) -> 178294.35 | O16: =SUM(O5:O7) -> 129088.56
L17: Total de Primavera | M17: =SUM(M8:M9) -> 87359.321 | N17: =SUM(N8:N9) -> 17197.398 | O17: =SUM(O8:O9) -> 70161.923
L18: Total de Sorriso | M18: =SUM(M10:M11) -> 96981.551 | N18: =SUM(N10:N11) -> 0 | O18: =SUM(O10:O11) -> 96981.551
L19: Acessos | M19: =SUM(M12:M13) -> 2674.4275 | N19: =SUM(N12:N13) -> 0 | O19: =SUM(O12:O13) -> 2674.4275
L20: Volume Total | M20: =SUM(M16:M19) -> 494398.21 | N20: =SUM(N16:N19) -> 195491.75 | O20: =SUM(O16:O19) -> 298906.46
